<?xml version="1.0"?>
<robot xmlns:xacro="http://www.ros.org/wiki/xacro" name="robot">

  <!-- Material Color -->
  <material name="blue">
    <color rgba="0 0 0.8 1"/>
  </material>

  <material name="yellow">
    <color rgba="0.8 0.8 0.0 1.0"/>
  </material>

  <material name="white">
    <color rgba="1 1 1 1"/>
  </material>


  <!-- Base Link -->
  <link name="base_link">
  </link>

<!-- BASE_FOOTPRINT LINK -->

  <joint name="base_footprint_joint" type="fixed">
    <parent link="base_link"/>
    <child link="base_footprint"/>
    <origin xyz="0 0 0" rpy="0 0 0"/>
  </joint>

  <link name="base_footprint">
  </link>

  <!-- Chassis link -->
  <link name="chassis">
    <visual>
      <origin xyz="0.35 0 0.01"/>
      <geometry>
        <box size="2.1 0.95 0.02"/>
      </geometry>
      <material name="blue"/>
    </visual>
    <collision>
      <origin xyz="0.35 0 0.01"/>
      <geometry>
        <box size="2.1 0.95 0.02"/>
      </geometry>
    </collision>
    <inertial>
      <origin xyz="0.35 0 0.01"/>
      <mass value="10.0"/>
      <inertia ixx="1.0" ixy="0.0" ixz="0.0" iyy="1.0" iyz="0.0" izz="1.0"/>
    </inertial>
  </link>

  <!-- Joint chassis -->
  <joint name="chassis_joint" type="fixed">
    <parent link="base_link"/>
    <child link="chassis"/>
    <origin xyz="-1 0 0"/>
  </joint>

  <!-- Right Wheel Link -->
  <link name="right_wheel">
    <visual>
      <geometry>
        <cylinder length="0.24" radius="0.3"/>
      </geometry>
      <material name="yellow"/>
    </visual>
    <collision>
      <geometry>
        <cylinder length="0.24" radius="0.3"/>
      </geometry>
    </collision>
    <inertial>
      <origin xyz="0 0 0"/>
      <mass value="1.0"/>
      <inertia ixx="0.02" ixy="0.0" ixz="0.0" iyy="0.02" iyz="0.0" izz="0.02"/>
    </inertial>
  </link>

  <!-- Joint between base_link and right wheel -->
  <joint name="base_to_right_wheel" type="continuous">
    <parent link="base_link"/>
    <child link="right_wheel"/>
    <origin xyz="-0.3 -0.475 -0.05" rpy="-1.5708 0 0"/>
    <axis xyz="0 0 -1"/>
    <dynamics damping="0.1" friction="0.1"/>
  </joint>

  <!-- Left Wheel Link -->
  <link name="left_wheel">
    <visual>
      <geometry>
        <cylinder length="0.24" radius="0.3"/>
      </geometry>
      <material name="yellow"/>
    </visual>
    <collision>
      <geometry>
        <cylinder length="0.24" radius="0.3"/>
      </geometry>
    </collision>
    <inertial>
      <origin xyz="0 0 0"/>
      <mass value="1.0"/>
      <inertia ixx="0.02" ixy="0.0" ixz="0.0" iyy="0.02" iyz="0.0" izz="0.02"/>
    </inertial>
  </link>

  <!-- Joint between base_link and left wheel -->
  <joint name="base_to_left_wheel" type="continuous">
    <parent link="base_link"/>
    <child link="left_wheel"/>
    <origin xyz="-0.3 0.475 -0.05" rpy="1.5708 0 0"/>
    <axis xyz="0 0 1"/>
    <dynamics damping="0.1" friction="0.1"/>
  </joint>

  <!-- Caster Wheel Setup -->
  <joint name="base_caster_wheel_joint" type="fixed">
    <parent link="chassis"/>
    <child link="base_caster_wheel"/>
    <origin xyz="-0.5 0 -0.06" rpy="0 0 0"/>
  </joint>

  <link name="base_caster_wheel">
    <visual>
      <geometry>
        <box size="0.36 0.36 0.12" />
      </geometry>
      <material name="blue"/>
    </visual>
    <collision>
      <geometry>
        <box size="0.36 0.36 0.12" />
      </geometry>
    </collision>
    <inertial>
      <origin xyz="0 0 0"/>
      <mass value="1.0"/>
      <inertia ixx="0.02" ixy="0.0" ixz="0.0" iyy="0.02" iyz="0.0" izz="0.02"/>
    </inertial>
  </link>

  <joint name="caster_wheel_joint" type="fixed">
    <parent link="base_caster_wheel"/>
    <child link="caster_wheel"/>
    <origin xyz="0 0 -0.15" rpy="0 0 0"/>
  </joint>

  <link name="caster_wheel">
    <visual>
      <geometry>
        <sphere radius="0.16" />
      </geometry>
      <material name="yellow"/>
    </visual>
    <collision>
      <geometry>
        <sphere radius="0.16" />
      </geometry>
    </collision>
    <inertial>
      <origin xyz="0 0 0"/>
      <mass value="1.0"/>
      <inertia ixx="0.02" ixy="0.0" ixz="0.0" iyy="0.02" iyz="0.0" izz="0.02"/>
    </inertial>
  </link>

</robot>
